<mujocoinclude>
    <body pos="0 0 0">
         <geom type="box" size=".2 .2 0.7" rgba="0 .9 0 1"/>
  </body>
  <body name='torso' pos='1 0 0' quat='0 0 0 1'>
      <geom type="box" size=".1 .1 0.7" rgba="0 .9 0 1"/>
      <geom name='base' type='capsule' class="panda_viz" fromto='0 0 0.7 0 0 1.2'  size='0.04 0.16' />
      <body name='right_upper_arm' pos='0 0 1.2' >
          <joint name='right_shoulder1' type='hinge' pos='0 0 0' axis='1 0 0' class="panda_arm" range='-85 60' stiffness='0' armature='0.0068' />
          <joint name='right_shoulder2' type='hinge' pos='0 0 0' axis='0 0 1' class="panda_arm" range='-85 60' stiffness='0'  armature='0.0051' />
          <geom name='right_uarm1' type='capsule' class="panda_viz" fromto='0 0 0 0 -0.28 0'  size='0.04 0.16' />
          <body name='right_lower_arm' pos='0 -0.3 0' >
               <joint name='right_elbow' type='hinge' pos='0 0 0' axis='0 0 1' class="panda_arm" range='-90 50'  stiffness='0' armature='0.0028' />
               <joint name='right_elbow2' type='hinge' pos='0 0 0' axis='0 1 0' class="panda_arm" range='-90 90'  stiffness='0' armature='0.0028' />

              <geom name='right_larm' type='capsule' class="panda_viz" fromto='0 -0.03 0 0 -0.3 0'  size='0.031' />
              <geom name='right_hand' type='sphere' class="panda_viz" pos='0 -0.3 0'  size='0.04'/>
              <geom name="ball_geom" rgba="0.8 0.6 0.6 1" type="cylinder" fromto="0.0 -0.3 0.25 0.0 -0.3 -0.05" size="0.028" density="2000" contype="2" conaffinity="1" />
              <site name="hand_down" pos='0 -0.3 0.25' size="0.01" />
              <site name="hand_up" pos='0 -0.3 -0.05' size="0.01" />
              <site name="hand_back" pos='0.05 -0.3 0.1' size="0.01" />
              <site name="object_down" pos='0 -0.3 0.25' size="0.01" />
              <site name="object_up" pos='0 -0.3 -0.05' size="0.01" />
              <site name="object_back" pos='0.05 -0.3 0.1' size="0.01" />


        </body>
    </body>
  </body>
</mujocoinclude>
