<mujocoinclude>
	<body name="panda0_link0" childclass="panda" pos="0 0 0.7" >
        <geom class="panda_viz" mesh="link0_viz"/>
        <geom class="panda_col" mesh="link0_col"/>
        <body name="panda0_link1" pos="0 0 0.333">
            <joint name="panda0_joint1" limited="true" range="-2.8973 2.8973" class="panda_arm"/>
            <geom class="panda_viz" mesh="link1_viz"/>
            <geom class="panda_col" mesh="link1_col"/>
            <body name="panda0_link2" pos="0 0 0" quat="0.707107 -0.707107 0 0">
                <joint name="panda0_joint2" limited="true" range="-1.7628 1.7628" class="panda_arm"/>
                <geom class="panda_viz" mesh="link2_viz"/>
                <geom class="panda_col" mesh="link2_col"/>
                <body name="panda0_link3" pos="0 -0.316 0" quat="0.707107 0.707107 0 0">
                    <joint name="panda0_joint3" limited="true" range="-2.8973 2.8973" class="panda_arm"/>
                    <geom class="panda_viz" mesh="link3_viz"/>
                    <geom class="panda_col" mesh="link3_col"/>
                    <body name="panda0_link4" pos="0.0825 0 0" quat="0.707107 0.707107 0 0">
                        <joint name="panda0_joint4" limited="true" range="-3.0718 -0.0698" class="panda_arm"/>
                        <geom class="panda_viz" mesh="link4_viz"/>
                        <geom class="panda_col" mesh="link4_col"/>
                        <body name="panda0_link5" pos="-0.0825 0.384 0" quat="0.707107 -0.707107 0 0">
                            <joint name="panda0_joint5" limited="true" range="-2.8973 2.8973" class="panda_forearm"/>
                            <geom class="panda_viz" mesh="link5_viz"/>
                            <geom class="panda_col" mesh="link5_col"/>
                            <body name="panda0_link6" pos="0 0 0" quat="0.707107 0.707107 0 0">
                                <joint name="panda0_joint6" limited="true" range="-0.0175 3.7525" class="panda_forearm"/>
                                <geom class="panda_viz" mesh="link6_viz"/>
                                <geom class="panda_col" mesh="link6_col"/>
                                <body name="panda0_link7" pos="0.088 0 0" quat="0.707107 0.707107 0 0">
                                    <joint name="panda0_joint7" limited="true" range="-2.8973 2.8973" class="panda_forearm"/>
                                    <geom class="panda_viz" quat="0.92388 0 0 0.382683" mesh="link7_viz"/>
                                    <geom class="panda_col" quat="0.92388 0 0 0.382683" mesh="link7_col"/>
                                    <geom pos="0 0 0.107"  class="panda_viz" mesh="hand_viz"/>
                                    <geom pos="0 0 0.107"  class="panda_col" mesh="hand_col"/>
																		<!-- <site name="gripper_bottom" pos="-0.15 0 0.2"  size="0.01" />
																		<site name="gripper_top" pos="0.15 0 0.2"  size="0.01" /> -->
                                                                        <!-- <site name="gripper_back" pos="0 0 0.15"  size="0.01" /> -->
                                    <site name="gripper_back" pos="0.0 0.0 0.0"  size="0.01" />
                                    <body name="panda0_leftfinger" pos="0 0 0.1654" >
                                        <!-- <joint name="panda0_finger_joint1"  axis="0 1 0" type="slide" range="0 0.04" class="panda_finger"/> -->
                                        <geom class="panda_viz" mesh="finger_viz"/>
                                        <geom class="panda_col" mesh="finger_col"/>
                                        <!-- <geom name="gripper_left_flat" pos="0 0 0.05" rgba="0 0.6 1 1" type="box" size="0.075 0.005 0.05" mass="0.01" density="1000" contype="1" conaffinity="1" solref=".02 0.5" solimp=".9 .9 .1" friction="1 1 1" /> -->
                                    </body>
                                    <body name="panda0_rightfinger" pos="0 0 0.1654" >
                                        <!-- <joint name="panda0_finger_joint2" axis="0 -1 0" type="slide" range="0 0.04" class="panda_finger"/> -->
                                        <geom quat="0 0 0 1" class="panda_viz" mesh="finger_viz"/>
                                        <geom quat="0 0 0 1" class="panda_col" mesh="finger_col"/>
                                        <!-- <geom name="gripper_right_flat" pos="0 0 0.05" rgba="0 0.6 1 1" type="box" size="0.075 0.005 0.05" mass="0.01" density="1000" contype="1" conaffinity="1" solref=".02 0.5" solimp=".9 .9 .1" friction="1 1 1" /> -->
                                    </body>
                                </body>
                            </body>
                        </body>
                    </body>
                </body>
            </body>
        </body>
    </body>

</mujocoinclude>
