<?xml version="1.0" encoding="utf-8"?>
<robot xmlns:xacro="http://www.ros.org/wiki/xacro" name="hand">
  <xacro:macro name="hand" params="connected_to:='' ns:='' rpy:='0 0 0' xyz:='0 0 0' ">
    <xacro:unless value="${connected_to == ''}">
      <joint name="${ns}_hand_joint" type="fixed">
        <parent link="${connected_to}"/>
        <child link="${ns}_hand"/>
        <origin xyz="${xyz}" rpy="${rpy}"/>
      </joint>
    </xacro:unless>

    <link name="${ns}_hand">
      <visual>
        <geometry>
          <mesh filename="package://franka_description/meshes/visual/hand.dae.dae"/>
        </geometry>
      </visual>
      <collision>
        <geometry>
          <mesh filename="package://franka_description/meshes/collision/hand.stl"/>
        </geometry>
        <contact_coefficient mu="0.8"  k_p="1"  k_d="1" />
      </collision>
      <inertial>
        <!-- ATTENTION! Needs to be defined correctly! -->
        <origin xyz="0 0 0.025" rpy="0 0 0"/>
        <mass value="1.0"/>
        <inertia ixx="0.001"  ixy="0"  ixz="0" iyy="0.001" iyz="0" izz="0.001" />
      </inertial>
    </link>

    <link name="${ns}_leftfinger">
      <visual>
        <geometry>
          <mesh filename="package://franka_description/meshes/visual/finger.dae.dae"/>
        </geometry>
      </visual>
      <collision>
        <geometry>
          <mesh filename="package://franka_description/meshes/collision/finger.stl"/>
        </geometry>
        <contact_coefficient mu="0.8"  k_p="100"  k_d="1" />
      </collision>
      <inertial>
        <!-- ATTENTION! Needs to be defined correctly! -->
        <origin xyz="0 0 0.02" rpy="0 0 0"/>
        <mass value="0.1"/>
        <inertia ixx="0.001"  ixy="0"  ixz="0" iyy="0.001" iyz="0" izz="0.001" />
      </inertial>
    </link>

    <link name="${ns}_rightfinger">
      <visual>
        <origin xyz="0 0 0" rpy="0 0 ${pi}"/>
        <geometry>
          <mesh filename="package://franka_description/meshes/visual/finger.dae.dae"/>
        </geometry>
      </visual>
      <collision>
        <origin xyz="0 0 0" rpy="0 0 ${pi}"/>
        <geometry>
          <mesh filename="package://franka_description/meshes/collision/finger.stl"/>
        </geometry>
        <contact_coefficient mu="0.8"  k_p="100"  k_d="1" />
      </collision>
      <inertial>
        <!-- ATTENTION! Needs to be defined correctly! -->
        <origin xyz="0 0 0.02" rpy="0 0 0"/>
        <mass value="0.1"/>
        <inertia ixx="0.001"  ixy="0"  ixz="0" iyy="0.001" iyz="0" izz="0.001" />
      </inertial>
    </link>

    <joint name="${ns}_finger_joint1" type="prismatic">
      <parent link="${ns}_hand"/>
      <child link="${ns}_leftfinger"/>
      <origin xyz="0 0 0.0584" rpy="0 0 0"/>
      <axis xyz="0 1 0"/>
      <limit effort="20" lower="0.0" upper="0.04" velocity="0.2"/>
      <dynamics damping="1" friction="0"/>
    </joint>
    <transmission name="${ns}_finger_transmission1">
      <type>transmission_interface/SimpleTransmission</type>
      <joint name="${ns}_finger_joint1">
	        <hardwareInterface>hardware_interface/EffortJointInterface</hardwareInterface>
      </joint>
      <actuator name="${ns}_finger_motor1">
	       <hardwareInterface>hardware_interface/EffortJointInterface</hardwareInterface>
	        <mechanicalReduction>1</mechanicalReduction>
      </actuator>
    </transmission>

    <joint name="${ns}_finger_joint2" type="prismatic">
      <parent link="${ns}_hand"/>
      <child link="${ns}_rightfinger"/>
      <origin xyz="0 0 0.0584" rpy="0 0 0"/>
      <axis xyz="0 -1 0"/>
      <limit effort="20" lower="0.0" upper="0.04" velocity="0.2"/>
      <dynamics damping="1" friction="0"/>
      <mimic joint="${ns}_finger_joint1" />
    </joint>
    <transmission name="${ns}_finger_transmission2">
      <type>transmission_interface/SimpleTransmission</type>
      <joint name="${ns}_finger_joint2">
	       <hardwareInterface>hardware_interface/EffortJointInterface</hardwareInterface>
      </joint>
      <actuator name="${ns}_finger_motor2">
	    <hardwareInterface>hardware_interface/EffortJointInterface</hardwareInterface>
	    <mechanicalReduction>1</mechanicalReduction>
      </actuator>
    </transmission>

    <link name="${ns}_tcp"/>
    <joint name="${ns}_hand_tcp_joint" type="fixed">
      <parent link="${ns}_hand"/>
      <child link="${ns}_tcp"/>
      <origin xyz="0 0 0.1025" rpy="0 0 0"/>
    </joint>

    <gazebo reference="${ns}_leftfinger">
        <kp>1000000.0</kp>
        <kd>1.0</kd>
        <mu1>0.3</mu1>
        <mu2>0.3</mu2>
        <minDepth>0.001</minDepth>
    </gazebo>
    <gazebo reference="${ns}_rightfinger">
        <kp>1000000.0</kp>
        <kd>1.0</kd>
        <mu1>0.3</mu1>
        <mu2>0.3</mu2>
        <minDepth>0.001</minDepth>
    </gazebo>
    <gazebo reference="${ns}_finger_joint1">
        <implicitSpringDamper>1</implicitSpringDamper>
    </gazebo>
    <gazebo reference="${ns}_finger_joint2">
        <implicitSpringDamper>1</implicitSpringDamper>
    </gazebo>

    <!-- Load gripper plugin. This plugin fixes an object which is grasped to the
         robot hand to avoid problems with physics engines and to help the object
         stay in the robot hand without slipping out -->
    <gazebo>
       <plugin name="gazebo_grasp_fix" filename="libgazebo_grasp_fix.so">
            <arm>
               <arm_name>gripper</arm_name>
               <palm_link>${ns}_link7</palm_link>
               <gripper_link>${ns}_leftfinger</gripper_link>
               <gripper_link>${ns}_rightfinger</gripper_link>
            </arm>
           <forces_angle_tolerance>150</forces_angle_tolerance>
           <update_rate>10</update_rate>
           <grip_count_threshold>3</grip_count_threshold>
           <max_grip_count>4</max_grip_count>
           <release_tolerance>0.001</release_tolerance>
           <disable_collisions_on_attach>false</disable_collisions_on_attach>
           <contact_topic>__default_topic__</contact_topic>
        </plugin>
    </gazebo>

  </xacro:macro>
</robot>
